Workbook

Sheet Dashboard
A1: DSA progress dashboard (unique problems only)
A2: Counts come only from the Tracker sheet. A problem counts once, when its status is solved (any of the 3 solved kinds) and its key has not already been counted.
A4: Overall | B4: Count
A5: Unique problems solved (any way) | B5: =SUM(Tracker!$V$2:$V$300)
A6: Solved independently | B6: =COUNTIFS(Tracker!$V$2:$V$300,1,Tracker!$J$2:$J$300,"Solved independently")
A7: Solved with hints | B7: =COUNTIFS(Tracker!$V$2:$V$300,1,Tracker!$J$2:$J$300,"Solved with hints")
A8: Solved after viewing solution | B8: =COUNTIFS(Tracker!$V$2:$V$300,1,Tracker!$J$2:$J$300,"Solved after viewing solution")
A9: Attempted but not solved | B9: =COUNTIF(Tracker!$J$2:$J$300,"Attempted")
A10: Independence rate | B10: =IF(B5=0,0,B6/B5)
A11: Revisions overdue | B11: =COUNTIFS(Tracker!$S$2:$S$300,"<="&TODAY(),Tracker!$S$2:$S$300,"<>")
A12: Rows with duplicate keys (fix these) | B12: =COUNTIF(Tracker!$W$2:$W$300,"DUPLICATE KEY")
A14: By platform (unique solves) | B14: Solved | C14: Independent
A15: LeetCode | B15: =SUMIFS(Tracker!$V$2:$V$300,Tracker!$C$2:$C$300,"LeetCode") | C15: =COUNTIFS(Tracker!$V$2:$V$300,1,Tracker!$C$2:$C$300,"LeetCode",Tracker!$J$2:$J$300,"Solved independently")
A16: HackerRank | B16: =SUMIFS(Tracker!$V$2:$V$300,Tracker!$C$2:$C$300,"HackerRank") | C16: =COUNTIFS(Tracker!$V$2:$V$300,1,Tracker!$C$2:$C$300,"HackerRank",Tracker!$J$2:$J$300,"Solved independently")
A17: GeeksforGeeks | B17: =SUMIFS(Tracker!$V$2:$V$300,Tracker!$C$2:$C$300,"GeeksforGeeks") | C17: =COUNTIFS(Tracker!$V$2:$V$300,1,Tracker!$C$2:$C$300,"GeeksforGeeks",Tracker!$J$2:$J$300,"Solved independently")
A18: CodeChef | B18: =SUMIFS(Tracker!$V$2:$V$300,Tracker!$C$2:$C$300,"CodeChef") | C18: =COUNTIFS(Tracker!$V$2:$V$300,1,Tracker!$C$2:$C$300,"CodeChef",Tracker!$J$2:$J$300,"Solved independently")
A19: Other | B19: =SUMIFS(Tracker!$V$2:$V$300,Tracker!$C$2:$C$300,"Other") | C19: =COUNTIFS(Tracker!$V$2:$V$300,1,Tracker!$C$2:$C$300,"Other",Tracker!$J$2:$J$300,"Solved independently")
A21: By difficulty (unique solves) | B21: Solved | C21: Independent
A22: Easy | B22: =SUMIFS(Tracker!$V$2:$V$300,Tracker!$F$2:$F$300,"Easy") | C22: =COUNTIFS(Tracker!$V$2:$V$300,1,Tracker!$F$2:$F$300,"Easy",Tracker!$J$2:$J$300,"Solved independently")
A23: Medium | B23: =SUMIFS(Tracker!$V$2:$V$300,Tracker!$F$2:$F$300,"Medium") | C23: =COUNTIFS(Tracker!$V$2:$V$300,1,Tracker!$F$2:$F$300,"Medium",Tracker!$J$2:$J$300,"Solved independently")
A24: Hard | B24: =SUMIFS(Tracker!$V$2:$V$300,Tracker!$F$2:$F$300,"Hard") | C24: =COUNTIFS(Tracker!$V$2:$V$300,1,Tracker!$F$2:$F$300,"Hard",Tracker!$J$2:$J$300,"Solved independently")
A26: By topic (unique solves) | B26: Solved | C26: Listed | D26: Independent
A27: Programming fundamentals & Big-O | B27: =SUMIFS(Tracker!$V$2:$V$300,Tracker!$E$2:$E$300,A27) | C27: =COUNTIF(Tracker!$E$2:$E$300,A27) | D27: =COUNTIFS(Tracker!$V$2:$V$300,1,Tracker!$E$2:$E$300,A27,Tracker!$J$2:$J$300,"Solved independently")
A28: Arrays & strings | B28: =SUMIFS(Tracker!$V$2:$V$300,Tracker!$E$2:$E$300,A28) | C28: =COUNTIF(Tracker!$E$2:$E$300,A28) | D28: =COUNTIFS(Tracker!$V$2:$V$300,1,Tracker!$E$2:$E$300,A28,Tracker!$J$2:$J$300,"Solved independently")
A29: Hashing & frequency counting | B29: =SUMIFS(Tracker!$V$2:$V$300,Tracker!$E$2:$E$300,A29) | C29: =COUNTIF(Tracker!$E$2:$E$300,A29) | D29: =COUNTIFS(Tracker!$V$2:$V$300,1,Tracker!$E$2:$E$300,A29,Tracker!$J$2:$J$300,"Solved independently")
A30: Two pointers | B30: =SUMIFS(Tracker!$V$2:$V$300,Tracker!$E$2:$E$300,A30) | C30: =COUNTIF(Tracker!$E$2:$E$300,A30) | D30: =COUNTIFS(Tracker!$V$2:$V$300,1,Tracker!$E$2:$E$300,A30,Tracker!$J$2:$J$300,"Solved independently")
A31: Sliding window | B31: =SUMIFS(Tracker!$V$2:$V$300,Tracker!$E$2:$E$300,A31) | C31: =COUNTIF(Tracker!$E$2:$E$300,A31) | D31: =COUNTIFS(Tracker!$V$2:$V$300,1,Tracker!$E$2:$E$300,A31,Tracker!$J$2:$J$300,"Solved independently")
A32: Sorting & binary search | B32: =SUMIFS(Tracker!$V$2:$V$300,Tracker!$E$2:$E$300,A32) | C32: =COUNTIF(Tracker!$E$2:$E$300,A32) | D32: =COUNTIFS(Tracker!$V$2:$V$300,1,Tracker!$E$2:$E$300,A32,Tracker!$J$2:$J$300,"Solved independently")
A33: Prefix sums, math & matrices | B33: =SUMIFS(Tracker!$V$2:$V$300,Tracker!$E$2:$E$300,A33) | C33: =COUNTIF(Tracker!$E$2:$E$300,A33) | D33: =COUNTIFS(Tracker!$V$2:$V$300,1,Tracker!$E$2:$E$300,A33,Tracker!$J$2:$J$300,"Solved independently")
A34: Bit manipulation | B34: =SUMIFS(Tracker!$V$2:$V$300,Tracker!$E$2:$E$300,A34) | C34: =COUNTIF(Tracker!$E$2:$E$300,A34) | D34: =COUNTIFS(Tracker!$V$2:$V$300,1,Tracker!$E$2:$E$300,A34,Tracker!$J$2:$J$300,"Solved independently")
A35: Recursion & backtracking | B35: =SUMIFS(Tracker!$V$2:$V$300,Tracker!$E$2:$E$300,A35) | C35: =COUNTIF(Tracker!$E$2:$E$300,A35) | D35: =COUNTIFS(Tracker!$V$2:$V$300,1,Tracker!$E$2:$E$300,A35,Tracker!$J$2:$J$300,"Solved independently")
A36: Linked lists | B36: =SUMIFS(Tracker!$V$2:$V$300,Tracker!$E$2:$E$300,A36) | C36: =COUNTIF(Tracker!$E$2:$E$300,A36) | D36: =COUNTIFS(Tracker!$V$2:$V$300,1,Tracker!$E$2:$E$300,A36,Tracker!$J$2:$J$300,"Solved independently")
A37: Stacks & queues | B37: =SUMIFS(Tracker!$V$2:$V$300,Tracker!$E$2:$E$300,A37) | C37: =COUNTIF(Tracker!$E$2:$E$300,A37) | D37: =COUNTIFS(Tracker!$V$2:$V$300,1,Tracker!$E$2:$E$300,A37,Tracker!$J$2:$J$300,"Solved independently")
A38: Trees & binary search trees | B38: =SUMIFS(Tracker!$V$2:$V$300,Tracker!$E$2:$E$300,A38) | C38: =COUNTIF(Tracker!$E$2:$E$300,A38) | D38: =COUNTIFS(Tracker!$V$2:$V$300,1,Tracker!$E$2:$E$300,A38,Tracker!$J$2:$J$300,"Solved independently")
... A43: Tries & advanced structures | B43: =SUMIFS(Tracker!$V$2:$V$300,Tracker!$E$2:$E$300,A43) | C43: =COUNTIF(Tracker!$E$2:$E$300,A43) | D43: =COUNTIFS(Tracker!$V$2:$V$300,1,Tracker!$E$2:$E$300,A43,Tracker!$J$2:$J$300,"Solved independently")
A45: Milestones | B45: Target | C45: Reached?
A46: Milestone: 25 unique solved | B46: 25 | C46: =IF(B5>=25,"Yes","Not yet")
A47: Milestone: 50 unique solved | B47: 50 | C47: =IF(B5>=50,"Yes","Not yet")
A48: Milestone: 100 unique solved | B48: 100 | C48: =IF(B5>=100,"Yes","Not yet")
A49: Milestone: 150 unique solved | B49: 150 | C49: =IF(B5>=150,"Yes","Not yet")
...

Sheet Tracker
A1: # | B1: Problem title | C1: Platform | D1: Problem URL | E1: Topic | F1: Difficulty | G1: Priority | H1: Week | I1: Date first attempted | J1: Status | K1: Solved independently? | L1: Attempts | M1: Time taken (min) | N1: Time complexity | O1: Space complexity | P1: Key lesson learned | Q1: Accepted on platform? (Y/N) | R1: Date solved | S1: Next revision due | T1: Revisions done | U1: Problem key (edit to match same problem across platforms) | V1: Counts as unique solve (auto) | W1: Duplicate warning (auto)
A2: 1 | B2: Solve Me First | C2: HackerRank | D2: Open | E2: Programming fundamentals & Big-O | F2: Easy | G2: Essential | H2: 1 | J2: Not started | K2: =IF(J2="Solved independently","Yes",IF(OR(J2="",J2="Not started"),"","No")) | S2: =IF(R2="","",R2+IF(T2=0,3,IF(T2=1,7,IF(T2=2,21,45)))) | U2: =IF(B2="","",LOWER(TRIM(B2))) | V2: =IF(AND(U2<>"",OR(J2="Solved independently",J2="Solved with hints",J2="Solved after viewing solution")),1,0) | W2: =IF(AND(U2<>"",COUNTIF($U$2:$U$300,U2)>1),"DUPLICATE KEY","")
A3: 2 | B3: Simple Array Sum | C3: HackerRank | D3: Open | E3: Programming fundamentals & Big-O | F3: Easy | G3: Essential | H3: 1 | J3: Not started | K3: =IF(J3="Solved independently","Yes",IF(OR(J3="",J3="Not started"),"","No")) | S3: =IF(R3="","",R3+IF(T3=0,3,IF(T3=1,7,IF(T3=2,21,45)))) | U3: =IF(B3="","",LOWER(TRIM(B3))) | V3: =IF(AND(U3<>"",OR(J3="Solved independently",J3="Solved with hints",J3="Solved after viewing solution"),COUNTIFS($U$2:U2,U3,$V$2:V2,1)=0),1,0) | W3: =IF(AND(U3<>"",COUNTIF($U$2:$U$300,U3)>1),"DUPLICATE KEY","")
A4: 3 | B4: Compare the Triplets | C4: HackerRank | D4: Open | E4: Programming fundamentals & Big-O | F4: Easy | G4: Recommended | H4: 1 | J4: Not started | K4: =IF(J4="Solved independently","Yes",IF(OR(J4="",J4="Not started"),"","No")) | S4: =IF(R4="","",R4+IF(T4=0,3,IF(T4=1,7,IF(T4=2,21,45)))) | U4: =IF(B4="","",LOWER(TRIM(B4))) | V4: =IF(AND(U4<>"",OR(J4="Solved independently",J4="Solved with hints",J4="Solved after viewing solution"),COUNTIFS($U$2:U3,U4,$V$2:V3,1)=0),1,0) | W4: =IF(AND(U4<>"",COUNTIF($U$2:$U$300,U4)>1),"DUPLICATE KEY","")
A5: 4 | B5: A Very Big Sum | C5: HackerRank | D5: Open | E5: Programming fundamentals & Big-O | F5: Easy | G5: Recommended | H5: 1 | J5: Not started | K5: =IF(J5="Solved independently","Yes",IF(OR(J5="",J5="Not started"),"","No")) | S5: =IF(R5="","",R5+IF(T5=0,3,IF(T5=1,7,IF(T5=2,21,45)))) | U5: =IF(B5="","",LOWER(TRIM(B5))) | V5: =IF(AND(U5<>"",OR(J5="Solved independently",J5="Solved with hints",J5="Solved after viewing solution"),COUNTIFS($U$2:U4,U5,$V$2:V4,1)=0),1,0) | W5: =IF(AND(U5<>"",COUNTIF($U$2:$U$300,U5)>1),"DUPLICATE KEY","")
A6: 5 | B6: Diagonal Difference | C6: HackerRank | D6: Open | E6: Programming fundamentals & Big-O | F6: Easy | G6: Recommended | H6: 1 | J6: Not started | K6: =IF(J6="Solved independently","Yes",IF(OR(J6="",J6="Not started"),"","No")) | S6: =IF(R6="","",R6+IF(T6=0,3,IF(T6=1,7,IF(T6=2,21,45)))) | U6: =IF(B6="","",LOWER(TRIM(B6))) | V6: =IF(AND(U6<>"",OR(J6="Solved independently",J6="Solved with hints",J6="Solved after viewing solution"),COUNTIFS($U$2:U5,U6,$V$2:V5,1)=0),1,0) | W6: =IF(AND(U6<>"",COUNTIF($U$2:$U$300,U6)>1),"DUPLICATE KEY","")
A7: 6 | B7: Plus Minus | C7: HackerRank | D7: Open | E7: Programming fundamentals & Big-O | F7: Easy | G7: Recommended | H7: 1 | J7: Not started | K7: =IF(J7="Solved independently","Yes",IF(OR(J7="",J7="Not started"),"","No")) | S7: =IF(R7="","",R7+IF(T7=0,3,IF(T7=1,7,IF(T7=2,21,45)))) | U7: =IF(B7="","",LOWER(TRIM(B7))) | V7: =IF(AND(U7<>"",OR(J7="Solved independently",J7="Solved with hints",J7="Solved after viewing solution"),COUNTIFS($U$2:U6,U7,$V$2:V6,1)=0),1,0) | W7: =IF(AND(U7<>"",COUNTIF($U$2:$U$300,U7)>1),"DUPLICATE KEY","")
A8: 7 | B8: Staircase | C8: HackerRank | D8: Open | E8: Programming fundamentals & Big-O | F8: Easy | G8: Recommended | H8: 1 | J8: Not started | K8: =IF(J8="Solved independently","Yes",IF(OR(J8="",J8="Not started"),"","No")) | S8: =IF(R8="","",R8+IF(T8=0,3,IF(T8=1,7,IF(T8=2,21,45)))) | U8: =IF(B8="","",LOWER(TRIM(B8))) | V8: =IF(AND(U8<>"",OR(J8="Solved independently",J8="Solved with hints",J8="Solved after viewing solution"),COUNTIFS($U$2:U7,U8,$V$2:V7,1)=0),1,0) | W8: =IF(AND(U8<>"",COUNTIF($U$2:$U$300,U8)>1),"DUPLICATE KEY","")
A9: 8 | B9: Mini-Max Sum | C9: HackerRank | D9: Open | E9: Programming fundamentals & Big-O | F9: Easy | G9: Recommended | H9: 1 | J9: Not started | K9: =IF(J9="Solved independently","Yes",IF(OR(J9="",J9="Not started"),"","No")) | S9: =IF(R9="","",R9+IF(T9=0,3,IF(T9=1,7,IF(T9=2,21,45)))) | U9: =IF(B9="","",LOWER(TRIM(B9))) | V9: =IF(AND(U9<>"",OR(J9="Solved independently",J9="Solved with hints",J9="Solved after viewing solution"),COUNTIFS($U$2:U8,U9,$V$2:V8,1)=0),1,0) | W9: =IF(AND(U9<>"",COUNTIF($U$2:$U$300,U9)>1),"DUPLICATE KEY","")
A10: 9 | B10: Birthday Cake Candles | C10: HackerRank | D10: Open | E10: Programming fundamentals & Big-O | F10: Easy | G10: Optional | H10: 1 | J10: Not started | K10: =IF(J10="Solved independently","Yes",IF(OR(J10="",J10="Not started"),"","No")) | S10: =IF(R10="","",R10+IF(T10=0,3,IF(T10=1,7,IF(T10=2,21,45)))) | U10: =IF(B10="","",LOWER(TRIM(B10))) | V10: =IF(AND(U10<>"",OR(J10="Solved independently",J10="Solved with hints",J10="Solved after viewing solution"),COUNTIFS($U$2:U9,U10,$V$2:V9,1)=0),1,0) | W10: =IF(AND(U10<>"",COUNTIF($U$2:$U$300,U10)>1),"DUPLICATE KEY","")
A11: 10 | B11: Time Conversion | C11: HackerRank | D11: Open | E11: Programming fundamentals & Big-O | F11: Easy | G11: Optional | H11: 1 | J11: Not started | K11: =IF(J11="Solved independently","Yes",IF(OR(J11="",J11="Not started"),"","No")) | S11: =IF(R11="","",R11+IF(T11=0,3,IF(T11=1,7,IF(T11=2,21,45)))) | U11: =IF(B11="","",LOWER(TRIM(B11))) | V11: =IF(AND(U11<>"",OR(J11="Solved independently",J11="Solved with hints",J11="Solved after viewing solution"),COUNTIFS($U$2:U10,U11,$V$2:V10,1)=0),1,0) | W11: =IF(AND(U11<>"",COUNTIF($U$2:$U$300,U11)>1),"DUPLICATE KEY","")
A12: 11 | B12: FizzBuzz | C12: LeetCode | D12: Open | E12: Programming fundamentals & Big-O | F12: Easy | G12: Essential | H12: 1 | J12: Not started | K12: =IF(J12="Solved independently","Yes",IF(OR(J12="",J12="Not started"),"","No")) | S12: =IF(R12="","",R12+IF(T12=0,3,IF(T12=1,7,IF(T12=2,21,45)))) | U12: =IF(B12="","",LOWER(TRIM(B12))) | V12: =IF(AND(U12<>"",OR(J12="Solved independently",J12="Solved with hints",J12="Solved after viewing solution"),COUNTIFS($U$2:U11,U12,$V$2:V11,1)=0),1,0) | W12: =IF(AND(U12<>"",COUNTIF($U$2:$U$300,U12)>1),"DUPLICATE KEY","")
A13: 12 | B13: Running Sum of 1d Array | C13: LeetCode | D13: Open | E13: Programming fundamentals & Big-O | F13: Easy | G13: Essential | H13: 1 | J13: Not started | K13: =IF(J13="Solved independently","Yes",IF(OR(J13="",J13="Not started"),"","No")) | S13: =IF(R13="","",R13+IF(T13=0,3,IF(T13=1,7,IF(T13=2,21,45)))) | U13: =IF(B13="","",LOWER(TRIM(B13))) | V13: =IF(AND(U13<>"",OR(J13="Solved independently",J13="Solved with hints",J13="Solved after viewing solution"),COUNTIFS($U$2:U12,U13,$V$2:V12,1)=0),1,0) | W13: =IF(AND(U13<>"",COUNTIF($U$2:$U$300,U13)>1),"DUPLICATE KEY","")
A14: 13 | B14: Contains Duplicate | C14: LeetCode | D14: Open | E14: Arrays & strings | F14: Easy | G14: Essential | H14: 1 | J14: Not started | K14: =IF(J14="Solved independently","Yes",IF(OR(J14="",J14="Not started"),"","No")) | S14: =IF(R14="","",R14+IF(T14=0,3,IF(T14=1,7,IF(T14=2,21,45)))) | U14: =IF(B14="","",LOWER(TRIM(B14))) | V14: =IF(AND(U14<>"",OR(J14="Solved independently",J14="Solved with hints",J14="Solved after viewing solution"),COUNTIFS($U$2:U13,U14,$V$2:V13,1)=0),1,0) | W14: =IF(AND(U14<>"",COUNTIF($U$2:$U$300,U14)>1),"DUPLICATE KEY","")
... A180: 179 | B180: Word Search II | C180: LeetCode | D180: Open | E180: Tries & advanced structures | F180: Hard | G180: Optional | H180: 10 | J180: Not started | K180: =IF(J180="Solved independently","Yes",IF(OR(J180="",J180="Not started"),"","No")) | S180: =IF(R180="","",R180+IF(T180=0,3,IF(T180=1,7,IF(T180=2,21,45)))) | U180: =IF(B180="","",LOWER(TRIM(B180))) | V180: =IF(AND(U180<>"",OR(J180="Solved independently",J180="Solved with hints",J180="Solved after viewing solution"),COUNTIFS($U$2:U179,U180,$V$2:V179,1)=0),1,0) | W180: =IF(AND(U180<>"",COUNTIF($U$2:$U$300,U180)>1),"DUPLICATE KEY","")
J181: Not started | K181: =IF(J181="Solved independently","Yes",IF(OR(J181="",J181="Not started"),"","No")) | S181: =IF(R181="","",R181+IF(T181=0,3,IF(T181=1,7,IF(T181=2,21,45)))) | U181: =IF(B181="","",LOWER(TRIM(B181))) | V181: =IF(AND(U181<>"",OR(J181="Solved independently",J181="Solved with hints",J181="Solved after viewing solution"),COUNTIFS($U$2:U180,U181,$V$2:V180,1)=0),1,0) | W181: =IF(AND(U181<>"",COUNTIF($U$2:$U$300,U181)>1),"DUPLICATE KEY","")
J182: Not started | K182: =IF(J182="Solved independently","Yes",IF(OR(J182="",J182="Not started"),"","No")) | S182: =IF(R182="","",R182+IF(T182=0,3,IF(T182=1,7,IF(T182=2,21,45)))) | U182: =IF(B182="","",LOWER(TRIM(B182))) | V182: =IF(AND(U182<>"",OR(J182="Solved independently",J182="Solved with hints",J182="Solved after viewing solution"),COUNTIFS($U$2:U181,U182,$V$2:V181,1)=0),1,0) | W182: =IF(AND(U182<>"",COUNTIF($U$2:$U$300,U182)>1),"DUPLICATE KEY","")
J183: Not started | K183: =IF(J183="Solved independently","Yes",IF(OR(J183="",J183="Not started"),"","No")) | S183: =IF(R183="","",R183+IF(T183=0,3,IF(T183=1,7,IF(T183=2,21,45)))) | U183: =IF(B183="","",LOWER(TRIM(B183))) | V183: =IF(AND(U183<>"",OR(J183="Solved independently",J183="Solved with hints",J183="Solved after viewing solution"),COUNTIFS($U$2:U182,U183,$V$2:V182,1)=0),1,0) | W183: =IF(AND(U183<>"",COUNTIF($U$2:$U$300,U183)>1),"DUPLICATE KEY","")
J184: Not started | K184: =IF(J184="Solved independently","Yes",IF(OR(J184="",J184="Not started"),"","No")) | S184: =IF(R184="","",R184+IF(T184=0,3,IF(T184=1,7,IF(T184=2,21,45)))) | U184: =IF(B184="","",LOWER(TRIM(B184))) | V184: =IF(AND(U184<>"",OR(J184="Solved independently",J184="Solved with hints",J184="Solved after viewing solution"),COUNTIFS($U$2:U183,U184,$V$2:V183,1)=0),1,0) | W184: =IF(AND(U184<>"",COUNTIF($U$2:$U$300,U184)>1),"DUPLICATE KEY","")
J185: Not started | K185: =IF(J185="Solved independently","Yes",IF(OR(J185="",J185="Not started"),"","No")) | S185: =IF(R185="","",R185+IF(T185=0,3,IF(T185=1,7,IF(T185=2,21,45)))) | U185: =IF(B185="","",LOWER(TRIM(B185))) | V185: =IF(AND(U185<>"",OR(J185="Solved independently",J185="Solved with hints",J185="Solved after viewing solution"),COUNTIFS($U$2:U184,U185,$V$2:V184,1)=0),1,0) | W185: =IF(AND(U185<>"",COUNTIF($U$2:$U$300,U185)>1),"DUPLICATE KEY","")
J186: Not started | K186: =IF(J186="Solved independently","Yes",IF(OR(J186="",J186="Not started"),"","No")) | S186: =IF(R186="","",R186+IF(T186=0,3,IF(T186=1,7,IF(T186=2,21,45)))) | U186: =IF(B186="","",LOWER(TRIM(B186))) | V186: =IF(AND(U186<>"",OR(J186="Solved independently",J186="Solved with hints",J186="Solved after viewing solution"),COUNTIFS($U$2:U185,U186,$V$2:V185,1)=0),1,0) | W186: =IF(AND(U186<>"",COUNTIF($U$2:$U$300,U186)>1),"DUPLICATE KEY","")
J187: Not started | K187: =IF(J187="Solved independently","Yes",IF(OR(J187="",J187="Not started"),"","No")) | S187: =IF(R187="","",R187+IF(T187=0,3,IF(T187=1,7,IF(T187=2,21,45)))) | U187: =IF(B187="","",LOWER(TRIM(B187))) | V187: =IF(AND(U187<>"",OR(J187="Solved independently",J187="Solved with hints",J187="Solved after viewing solution"),COUNTIFS($U$2:U186,U187,$V$2:V186,1)=0),1,0) | W187: =IF(AND(U187<>"",COUNTIF($U$2:$U$300,U187)>1),"DUPLICATE KEY","")
J188: Not started | K188: =IF(J188="Solved independently","Yes",IF(OR(J188="",J188="Not started"),"","No")) | S188: =IF(R188="","",R188+IF(T188=0,3,IF(T188=1,7,IF(T188=2,21,45)))) | U188: =IF(B188="","",LOWER(TRIM(B188))) | V188: =IF(AND(U188<>"",OR(J188="Solved independently",J188="Solved with hints",J188="Solved after viewing solution"),COUNTIFS($U$2:U187,U188,$V$2:V187,1)=0),1,0) | W188: =IF(AND(U188<>"",COUNTIF($U$2:$U$300,U188)>1),"DUPLICATE KEY","")
J189: Not started | K189: =IF(J189="Solved independently","Yes",IF(OR(J189="",J189="Not started"),"","No")) | S189: =IF(R189="","",R189+IF(T189=0,3,IF(T189=1,7,IF(T189=2,21,45)))) | U189: =IF(B189="","",LOWER(TRIM(B189))) | V189: =IF(AND(U189<>"",OR(J189="Solved independently",J189="Solved with hints",J189="Solved after viewing solution"),COUNTIFS($U$2:U188,U189,$V$2:V188,1)=0),1,0) | W189: =IF(AND(U189<>"",COUNTIF($U$2:$U$300,U189)>1),"DUPLICATE KEY","")
J190: Not started | K190: =IF(J190="Solved independently","Yes",IF(OR(J190="",J190="Not started"),"","No")) | S190: =IF(R190="","",R190+IF(T190=0,3,IF(T190=1,7,IF(T190=2,21,45)))) | U190: =IF(B190="","",LOWER(TRIM(B190))) | V190: =IF(AND(U190<>"",OR(J190="Solved independently",J190="Solved with hints",J190="Solved after viewing solution"),COUNTIFS($U$2:U189,U190,$V$2:V189,1)=0),1,0) | W190: =IF(AND(U190<>"",COUNTIF($U$2:$U$300,U190)>1),"DUPLICATE KEY","")
J191: Not started | K191: =IF(J191="Solved independently","Yes",IF(OR(J191="",J191="Not started"),"","No")) | S191: =IF(R191="","",R191+IF(T191=0,3,IF(T191=1,7,IF(T191=2,21,45)))) | U191: =IF(B191="","",LOWER(TRIM(B191))) | V191: =IF(AND(U191<>"",OR(J191="Solved independently",J191="Solved with hints",J191="Solved after viewing solution"),COUNTIFS($U$2:U190,U191,$V$2:V190,1)=0),1,0) | W191: =IF(AND(U191<>"",COUNTIF($U$2:$U$300,U191)>1),"DUPLICATE KEY","")
J192: Not started | K192: =IF(J192="Solved independently","Yes",IF(OR(J192="",J192="Not started"),"","No")) | S192: =IF(R192="","",R192+IF(T192=0,3,IF(T192=1,7,IF(T192=2,21,45)))) | U192: =IF(B192="","",LOWER(TRIM(B192))) | V192: =IF(AND(U192<>"",OR(J192="Solved independently",J192="Solved with hints",J192="Solved after viewing solution"),COUNTIFS($U$2:U191,U192,$V$2:V191,1)=0),1,0) | W192: =IF(AND(U192<>"",COUNTIF($U$2:$U$300,U192)>1),"DUPLICATE KEY","")
... J300: Not started | K300: =IF(J300="Solved independently","Yes",IF(OR(J300="",J300="Not started"),"","No")) | S300: =IF(R300="","",R300+IF(T300=0,3,IF(T300=1,7,IF(T300=2,21,45)))) | U300: =IF(B300="","",LOWER(TRIM(B300))) | V300: =IF(AND(U300<>"",OR(J300="Solved independently",J300="Solved with hints",J300="Solved after viewing solution"),COUNTIFS($U$2:U299,U300,$V$2:V299,1)=0),1,0) | W300: =IF(AND(U300<>"",COUNTIF($U$2:$U$300,U300)>1),"DUPLICATE KEY","")

Sheet Verification log
A1: Platform | B1: Profile URL | C1: Date checked | D1: Platform-reported solved count | E1: My tracker's unique count | F1: Screenshot/PDF saved? (Y/N) | G1: Notes (e.g. counts include premium/duplicates?)
A2: LeetCode
A3: HackerRank
A4: GeeksforGeeks
A5: CodeChef
A8: Update monthly. Quote platform counts as 'platform-reported'. Quote your tracker count as your own record. Only put a number on a resume that you have just confirmed on your live profile.

Sheet Mock log
A1: Date | B1: Type (OA / timed set / interview) | C1: Source | D1: Problems given | E1: Fully solved (all tests) | F1: Partially solved | G1: Time used / limit (min) | H1: Where I lost time | I1: Weak topics exposed | J1: Action for next week

Sheet Weekly review
A1: Week | B1: Week start | C1: New problems solved | D1: Revisions done | E1: Solved independently (of new) | F1: Avg minutes per Easy | G1: Avg minutes per Medium | H1: Strongest topic | I1: Weakest topic | J1: Decision: advance / repeat / add problems | K1: Change for next week
A2: 1
A3: 2
A4: 3
A5: 4
A6: 5
A7: 6
A8: 7
A9: 8
A10: 9
A11: 10
A12: 11
A13: 12
... A15: 14

Sheet Problem list
A1: Order | B1: Week | C1: Topic | D1: Problem | E1: Platform | F1: Link | G1: Difficulty | H1: Concept tested | I1: Prerequisites | J1: Priority
A2: 1 | B2: 1 | C2: Programming fundamentals & Big-O | D2: Solve Me First | E2: HackerRank | F2: https://www.hackerrank.com/challenges/solve-me-first/problem | G2: Easy | H2: I/O and submission workflow | I2: Python basics | J2: Essential
A3: 2 | B3: 1 | C3: Programming fundamentals & Big-O | D3: Simple Array Sum | E3: HackerRank | F3: https://www.hackerrank.com/challenges/simple-array-sum/problem | G3: Easy | H3: Loops, arrays | I3: Python basics | J3: Essential
A4: 3 | B4: 1 | C4: Programming fundamentals & Big-O | D4: Compare the Triplets | E4: HackerRank | F4: https://www.hackerrank.com/challenges/compare-the-triplets/problem | G4: Easy | H4: Conditionals, indexing | I4: Python basics | J4: Recommended
A5: 4 | B5: 1 | C5: Programming fundamentals & Big-O | D5: A Very Big Sum | E5: HackerRank | F5: https://www.hackerrank.com/challenges/a-very-big-sum/problem | G5: Easy | H5: Integers, accumulation | I5: Python basics | J5: Recommended
A6: 5 | B6: 1 | C6: Programming fundamentals & Big-O | D6: Diagonal Difference | E6: HackerRank | F6: https://www.hackerrank.com/challenges/diagonal-difference/problem | G6: Easy | H6: 2D arrays | I6: Python basics | J6: Recommended
A7: 6 | B7: 1 | C7: Programming fundamentals & Big-O | D7: Plus Minus | E7: HackerRank | F7: https://www.hackerrank.com/challenges/plus-minus/problem | G7: Easy | H7: Counting, formatting | I7: Python basics | J7: Recommended
A8: 7 | B8: 1 | C8: Programming fundamentals & Big-O | D8: Staircase | E8: HackerRank | F8: https://www.hackerrank.com/challenges/staircase/problem | G8: Easy | H8: Nested loops, strings | I8: Python basics | J8: Recommended
A9: 8 | B9: 1 | C9: Programming fundamentals & Big-O | D9: Mini-Max Sum | E9: HackerRank | F9: https://www.hackerrank.com/challenges/mini-max-sum/problem | G9: Easy | H9: Sum/min/max | I9: Python basics | J9: Recommended
A10: 9 | B10: 1 | C10: Programming fundamentals & Big-O | D10: Birthday Cake Candles | E10: HackerRank | F10: https://www.hackerrank.com/challenges/birthday-cake-candles/problem | G10: Easy | H10: Max and counting | I10: Python basics | J10: Optional
A11: 10 | B11: 1 | C11: Programming fundamentals & Big-O | D11: Time Conversion | E11: HackerRank | F11: https://www.hackerrank.com/challenges/time-conversion/problem | G11: Easy | H11: String parsing | I11: Python basics | J11: Optional
A12: 11 | B12: 1 | C12: Programming fundamentals & Big-O | D12: FizzBuzz | E12: LeetCode | F12: https://leetcode.com/problems/fizz-buzz/ | G12: Easy | H12: Loops, modulo | I12: Python basics | J12: Essential
A13: 12 | B13: 1 | C13: Programming fundamentals & Big-O | D13: Running Sum of 1d Array | E13: LeetCode | F13: https://leetcode.com/problems/running-sum-of-1d-array/ | G13: Easy | H13: Prefix idea | I13: Python basics | J13: Essential
... A180: 179 | B180: 10 | C180: Tries & advanced structures | D180: Word Search II | E180: LeetCode | F180: https://leetcode.com/problems/word-search-ii/ | G180: Hard | H180: Trie + grid backtracking | I180: Trees, hashing | J180: Optional
